<?xml version="1.0" ?>
<!-- Generated using onshape-to-robot -->
<!-- Onshape https://cad.onshape.com/documents/804927696f06d877f3f1803e/w/12cb1084d6a5622fc1b3935e/e/eee1ab796d84f4ff324d3a02 -->
<mujoco model="microduck">
  <compiler angle="radian" meshdir="assets" autolimits="true"/>
  <default>
    <default class="microduck">
      <joint frictionloss="0.1" armature="0.005"/>
      <position kp="50" dampratio="1"/>
      <default class="visual">
        <geom type="mesh" contype="0" conaffinity="0" group="2"/>
      </default>
      <default class="collision">
        <geom group="3"/>
      </default>
    </default>
  </default>
  <!-- Additional joints_properties.xml -->
  <default>
    <default class="perfect_actuator">
      <geom contype="0" conaffinity="0"/>
      <joint damping="0.15" frictionloss="0.1" armature="0.001"/>
      <position kp="10.0" kv="0.1" forcerange="-20.0 20.0"/>
    </default>
    <default class="xc330m288t">
      <!-- probably wrong, would need to re-identify -->
      <geom contype="0" conaffinity="0"/>
      <joint damping="0.095" frictionloss="0.058" armature="0.0018"/>
      <position kp="2.54" kv="0.0" forcerange="-0.8 0.8"/>
      <default class="chosen_actuator"/>
    </default>
  </default>
  <!-- Additional sensors.xml -->
  <sensor>
    <framequat name="orientation" objtype="site" noise="0.001" objname="imu"/>
    <gyro name="angular-velocity" site="imu" noise="0.005"/>
    <gyro name="imu_ang_vel" site="imu"/>
    <velocimeter name="imu_lin_vel" site="imu"/>
    <subtreeangmom name="root_angmom" body="trunk"/>
  </sensor>
  <worldbody>
    <!-- Link trunk -->
    <body name="trunk" pos="0 0 0.15" quat="1 0 0 0" childclass="microduck">
      <freejoint name="trunk_freejoint"/>
      <inertial pos="-0.00570087 -3.43986e-05 -0.010002" mass="0.126288" fullinertia="0.000123171 0.000122731 7.14541e-05 1.10562e-07 -5.90477e-06 9.14659e-08"/>
      <!-- Part xl330 -->
      <geom type="mesh" class="visual" pos="-0.00525 -0.02 0.004025" quat="0 -0.707107 0 -0.707107" mesh="xl330" material="xl330_material"/>
      <!-- Part bearing -->
      <geom type="mesh" class="visual" pos="-0.00525 -0.04 0.003925" quat="1 0 0 0" mesh="bearing" material="bearing_material"/>
      <!-- Part xl330_2 -->
      <geom type="mesh" class="visual" pos="-0.00525 0.02 0.004025" quat="1.96262e-17 0.707107 -0 0.707107" mesh="xl330" material="xl330_material"/>
      <!-- Part xl330_3 -->
      <geom type="mesh" class="visual" pos="0.01975 0.0001 0.020925" quat="0.707107 1.77773e-16 -2.22045e-16 0.707107" mesh="xl330" material="xl330_material"/>
      <!-- Part bearing_2 -->
      <geom type="mesh" class="visual" pos="-0.00525 -1.38778e-17 0.003925" quat="1 0 0 0" mesh="bearing" material="bearing_material"/>
      <!-- Part trunk -->
      <geom type="mesh" class="visual" pos="-0.00525 0 0.003925" quat="1 -0 1.11022e-16 1.11022e-16" mesh="trunk" material="trunk_material"/>
      <!-- Frame imu -->
      <site group="3" name="imu" pos="-0.02285 -7.75301e-18 0.015525" quat="1 -0 1.11022e-16 1.11022e-16"/>
      <!-- Link roll_motor_bottom -->
      <body name="roll_motor_bottom" pos="-0.00525 0.02 -0.010475" quat="0.707107 -0 -5.55112e-17 -0.707107">
        <!-- Joint from trunk to roll_motor_bottom -->
        <joint axis="0 0 1" name="left_hip_yaw" type="hinge" range="-0.3490658503988659 0.3490658503988659" class="chosen_actuator"/>
        <inertial pos="4.11329e-18 0.000232696 -0.0210443" mass="0.0258974" fullinertia="5.90117e-06 5.32544e-06 2.52712e-06 -4.14756e-23 3.46673e-21 -2.26655e-08"/>
        <!-- Part roll_motor_bottom -->
        <geom type="mesh" class="visual" pos="0.02 5e-05 0.0146" quat="0.707107 -1.01153e-17 -1.11022e-16 0.707107" mesh="roll_motor_bottom" material="roll_motor_bottom_material"/>
        <!-- Part roll_motor_top -->
        <geom type="mesh" class="visual" pos="0.02 8.67362e-19 0.0146" quat="0.707107 -5.67886e-17 0 0.707107" mesh="roll_motor_top" material="roll_motor_top_material"/>
        <!-- Part xl330_4 -->
        <geom type="mesh" class="visual" pos="1.38778e-17 5e-05 -0.0286" quat="1.09661e-16 -0.707107 0.707107 -3.91646e-18" mesh="xl330" material="xl330_material"/>
        <!-- Link left_roll_to_pitch -->
        <body name="left_roll_to_pitch" pos="1.04083e-17 0.01455 -0.0286" quat="4.2575e-16 -2.44153e-17 -0.707107 0.707107">
          <!-- Joint from roll_motor_bottom to left_roll_to_pitch -->
          <joint axis="0 0 1" name="left_hip_roll" type="hinge" range="-0.6981317007977318 0.6981317007977318" class="chosen_actuator"/>
          <inertial pos="0.0345835 -9.39115e-21 0.0134753" mass="0.0311996" fullinertia="5.49708e-06 9.80988e-06 6.94591e-06 3.67647e-21 5.3922e-08 2.68673e-21"/>
          <!-- Part left_roll_to_pitch -->
          <geom type="mesh" class="visual" pos="-0.02 -0.0432 0.0145" quat="0.5 0.5 0.5 -0.5" mesh="left_roll_to_pitch" material="left_roll_to_pitch_material"/>
          <!-- Part xl330_5 -->
          <geom type="mesh" class="visual" pos="0.0399 -1.38778e-17 0.0245" quat="5.21797e-18 6.93889e-17 -2.22045e-16 -1" mesh="xl330" material="xl330_material"/>
          <!-- Link leg_plate -->
          <body name="leg_plate" pos="0.0544 -1.38778e-17 0.0245" quat="0.5 0.5 -0.5 -0.5">
            <!-- Joint from left_roll_to_pitch to leg_plate -->
            <joint axis="0 0 1" name="left_hip_pitch" type="hinge" range="-1.5707963267948966 0.0" class="chosen_actuator"/>
            <inertial pos="-0.0288828 -8.61069e-20 0.0142685" mass="0.0265433" fullinertia="3.80505e-06 7.35131e-06 5.5313e-06 -7.20127e-22 -2.52969e-08 5.88852e-22"/>
            <!-- Part leg_plate -->
            <geom type="mesh" class="visual" pos="0.0432 0.01 -0.0455" quat="0.5 0.5 0.5 0.5" mesh="leg_plate" material="leg_plate_material"/>
            <!-- Part leg_plate_2 -->
            <geom type="mesh" class="visual" pos="0.0432 -0.01 0.0745" quat="0.5 -0.5 0.5 -0.5" mesh="leg_plate" material="leg_plate_material"/>
            <!-- Part xl330_6 -->
            <geom type="mesh" class="visual" pos="-0.042 -3.46945e-18 0.0145" quat="0.707107 -1.05148e-16 -0.707107 1.52482e-16" mesh="xl330" material="xl330_material"/>
            <!-- Link leg_plate_2 -->
            <body name="leg_plate_2" pos="-0.042 -8.67362e-18 4.16334e-17" quat="0.707107 -9.82347e-17 1.38778e-16 0.707107">
              <!-- Joint from leg_plate to leg_plate_2 -->
              <joint axis="0 0 1" name="left_knee" type="hinge" range="0.0 1.9198621771937625" class="chosen_actuator"/>
              <inertial pos="-1.53369e-17 0.0288828 0.0142685" mass="0.0265433" fullinertia="7.35131e-06 3.80505e-06 5.5313e-06 8.71771e-22 1.27215e-21 2.52969e-08"/>
              <!-- Part leg_plate_3 -->
              <geom type="mesh" class="visual" pos="-0.01 -0.0432 0.0745" quat="3.54329e-17 -0 -0.707107 0.707107" mesh="leg_plate" material="leg_plate_material"/>
              <!-- Part leg_plate_4 -->
              <geom type="mesh" class="visual" pos="0.01 -0.0432 -0.0455" quat="0.707107 0.707107 6.66134e-16 -7.06388e-16" mesh="leg_plate" material="leg_plate_material"/>
              <!-- Part xl330_7 -->
              <geom type="mesh" class="visual" pos="-1.9082e-17 0.042 0.0145" quat="0.5 -0.5 -0.5 -0.5" mesh="xl330" material="xl330_material"/>
              <!-- Link foot -->
              <body name="foot" pos="-2.08167e-17 0.042 0" quat="1 -0 -2.08167e-17 1.64327e-16">
                <!-- Joint from leg_plate_2 to foot -->
                <joint axis="0 0 1" name="left_ankle" type="hinge" range="-1.5707963267948966 1.5707963267948966" class="chosen_actuator"/>
                <inertial pos="-0.00535915 0.0128708 0.0145" mass="0.0227748" fullinertia="2.77519e-06 6.82595e-06 5.4299e-06 2.22912e-08 3.15968e-12 1.93034e-11"/>
                <!-- Part foot -->
                <geom type="mesh" class="visual" pos="-0.01 -0.1272 0.0745" quat="6.02089e-18 -1.33381e-19 -0.707107 0.707107" mesh="foot" material="foot_material"/>
                <geom name="left_foot_collision" type="mesh" class="collision" pos="-0.01 -0.1272 0.0745" quat="6.02089e-18 -1.33381e-19 -0.707107 0.707107" mesh="foot" material="foot_material"/>
                <!-- Frame left_foot -->
                <site group="3" name="left_foot" pos="-0.00549715 0.021 0.0145" quat="6.02089e-18 -1.33381e-19 -0.707107 0.707107"/>
              </body>
            </body>
          </body>
        </body>
      </body>
      <!-- Link neck_plate -->
      <body name="neck_plate" pos="0.01975 0.0146 0.020925" quat="0 0 -0.707107 0.707107">
        <!-- Joint from trunk to neck_plate -->
        <joint axis="0 0 1" name="neck_pitch" type="hinge" range="-1.2217304763960306 1.2217304763960306" class="chosen_actuator"/>
        <inertial pos="3.21257e-18 -0.0296987 0.0147301" mass="0.0266987" fullinertia="7.55113e-06 3.85092e-06 5.69714e-06 -6.37297e-22 -1.75911e-21 2.64276e-08"/>
        <!-- Part neck_plate -->
        <geom type="mesh" class="visual" pos="-0.025 0.017 0.0145" quat="0.707107 0.707107 -0 -0" mesh="neck_plate" material="neck_plate_material"/>
        <!-- Part neck_plate_2 -->
        <geom type="mesh" class="visual" pos="0.025 0.017 0.0145" quat="0 0 -0.707107 0.707107" mesh="neck_plate" material="neck_plate_material"/>
        <!-- Part xl330_8 -->
        <geom type="mesh" class="visual" pos="0 -0.043 0.0145" quat="0.5 0.5 0.5 -0.5" mesh="xl330" material="xl330_material"/>
        <!-- Link head_pitch_to_yaw -->
        <body name="head_pitch_to_yaw" pos="0 -0.043 -1.73472e-18" quat="1 2.51409e-16 -0 -0">
          <!-- Joint from neck_plate to head_pitch_to_yaw -->
          <joint axis="0 0 1" name="head_pitch" type="hinge" range="-1.2217304763960306 1.2217304763960306" class="chosen_actuator"/>
          <inertial pos="0.00612022 -0.0212216 0.0145" mass="0.00847041" fullinertia="3.01296e-06 1.50757e-06 2.61412e-06 4.42309e-07 1.0103e-12 2.76775e-13"/>
          <!-- Part head_pitch_to_yaw -->
          <geom type="mesh" class="visual" pos="0.025 0.06 0.0145" quat="0 0 -0.707107 0.707107" mesh="head_pitch_to_yaw" material="head_pitch_to_yaw_material"/>
          <!-- Link head_yaw_to_roll -->
          <body name="head_yaw_to_roll" pos="6.93889e-18 -0.0465 0.0145" quat="0 0 -0.707107 0.707107">
            <!-- Joint from head_pitch_to_yaw to head_yaw_to_roll -->
            <joint axis="0 0 1" name="head_yaw" type="hinge" range="-2.6179938779914944 2.6179938779914944" class="chosen_actuator"/>
            <inertial pos="0.00606296 1.25159e-17 -0.0188255" mass="0.0390317" fullinertia="7.80533e-06 1.6621e-05 1.70678e-05 3.12972e-22 -9.91967e-07 1.49772e-21"/>
            <!-- Part head_yaw_to_roll -->
            <geom type="mesh" class="visual" pos="-0.025 2.06676e-17 -0.1065" quat="1 0 0 0" mesh="head_yaw_to_roll" material="head_yaw_to_roll_material"/>
            <!-- Part xl330_9 -->
            <geom type="mesh" class="visual" pos="0 -1.49078e-19 -0.0145" quat="0.707107 0 -0.707107 0" mesh="xl330" material="xl330_material"/>
            <!-- Link head_base_plate -->
            <body name="head_base_plate" pos="0.0305 2.06676e-17 -0.0145" quat="0.5 -0.5 -0.5 0.5">
              <!-- Joint from head_yaw_to_roll to head_base_plate -->
              <joint axis="0 0 1" name="head_roll" type="hinge" range="-0.5235987755982988 0.5235987755982988" class="chosen_actuator"/>
              <inertial pos="0.0025688 0.00776484 0.0206149" mass="0.0757714" fullinertia="0.000156688 0.000175724 3.44851e-05 1.56046e-06 7.66338e-06 -7.49645e-06"/>
              <!-- Part xl330_10 -->
              <geom type="mesh" class="visual" pos="0 0 -0.0145" quat="0.707107 0 -0.707107 0" mesh="xl330" material="xl330_material"/>
              <!-- Part bearing_3 -->
              <geom type="mesh" class="visual" pos="-0.02 2.77556e-17 0.1215" quat="0.707107 -8.17756e-17 0 -0.707107" mesh="bearing" material="bearing_material"/>
              <!-- Part head_base_plate -->
              <geom type="mesh" class="visual" pos="1.38778e-17 0.092 0.0556" quat="0.5 0.5 0.5 -0.5" mesh="head_base_plate" material="head_base_plate_material"/>
            </body>
          </body>
        </body>
      </body>
      <!-- Link xl330 -->
      <body name="xl330" pos="-0.00525 -0.02 -0.010475" quat="1 -0 -2.47112e-17 9.12594e-33">
        <!-- Joint from trunk to xl330 -->
        <joint axis="0 0 1" name="right_hip_yaw" type="hinge" range="-0.3490658503988659 0.3490658503988659" class="chosen_actuator"/>
        <inertial pos="0.000232696 -8.98086e-18 -0.0210443" mass="0.0258974" fullinertia="5.32544e-06 5.90117e-06 2.52712e-06 2.24554e-23 -2.26655e-08 -4.13403e-21"/>
        <!-- Part roll_motor_top_2 -->
        <geom type="mesh" class="visual" pos="8.67362e-19 -0.02 0.0146" quat="1 -8.03113e-17 -2.22045e-16 5.55112e-17" mesh="roll_motor_top" material="roll_motor_top_material"/>
        <!-- Part roll_motor_bottom_2 -->
        <geom type="mesh" class="visual" pos="5e-05 -0.02 0.0146" quat="1 -8.03113e-17 0 -1.48602e-16" mesh="roll_motor_bottom" material="roll_motor_bottom_material"/>
        <!-- Part xl330_11 -->
        <geom type="mesh" class="visual" pos="5e-05 -1.73472e-17 -0.0286" quat="7.47726e-17 0 1 -8.03113e-17" mesh="xl330" material="xl330_material"/>
        <!-- Link right_roll_to_pitch -->
        <body name="right_roll_to_pitch" pos="0.01455 -1.73472e-17 -0.0286" quat="0.5 -0.5 -0.5 0.5">
          <!-- Joint from xl330 to right_roll_to_pitch -->
          <joint axis="0 0 1" name="right_hip_roll" type="hinge" range="-0.6981317007977318 0.6981317007977318" class="chosen_actuator"/>
          <inertial pos="-0.0343051 1.89346e-17 0.0134753" mass="0.0311996" fullinertia="5.49708e-06 9.71334e-06 6.84937e-06 -1.5009e-21 -6.39367e-08 1.13639e-21"/>
          <!-- Part right_roll_to_pitch -->
          <geom type="mesh" class="visual" pos="0.02 -0.0432 0.0145" quat="0.5 0.5 0.5 -0.5" mesh="right_roll_to_pitch" material="right_roll_to_pitch_material"/>
          <!-- Part xl330_12 -->
          <geom type="mesh" class="visual" pos="-0.0401 1.38778e-17 0.0245" quat="1.07294e-17 0 -6.93889e-18 1" mesh="xl330" material="xl330_material"/>
          <!-- Link xl330_2 -->
          <body name="xl330_2" pos="-0.0546 1.38778e-17 0.0245" quat="0.5 -0.5 0.5 -0.5">
            <!-- Joint from right_roll_to_pitch to xl330_2 -->
            <joint axis="0 0 1" name="right_hip_pitch" type="hinge" range="0.0 1.5707963267948966" class="chosen_actuator"/>
            <inertial pos="-0.0288828 -4.71416e-19 0.0142685" mass="0.0265433" fullinertia="3.80505e-06 7.35131e-06 5.5313e-06 -3.33448e-22 -2.52969e-08 5.61224e-22"/>
            <!-- Part xl330_13 -->
            <geom type="mesh" class="visual" pos="-0.042 -3.46945e-18 0.0145" quat="0.707107 9.97848e-17 -0.707107 -2.75391e-16" mesh="xl330" material="xl330_material"/>
            <!-- Part leg_plate_5 -->
            <geom type="mesh" class="visual" pos="0.0432 0.01 -0.0455" quat="0.5 0.5 0.5 0.5" mesh="leg_plate" material="leg_plate_material"/>
            <!-- Part leg_plate_6 -->
            <geom type="mesh" class="visual" pos="0.0432 -0.01 0.0745" quat="0.5 -0.5 0.5 -0.5" mesh="leg_plate" material="leg_plate_material"/>
            <!-- Link xl330_3 -->
            <body name="xl330_3" pos="-0.042 -3.46945e-18 2.77556e-17" quat="0.707107 8.62279e-17 0 0.707107">
              <!-- Joint from xl330_2 to xl330_3 -->
              <joint axis="0 0 1" name="right_knee" type="hinge" range="-1.9198621771937616 8.881784197001252e-16" class="chosen_actuator"/>
              <inertial pos="-3.26312e-17 0.0288828 0.0142685" mass="0.0265433" fullinertia="7.35131e-06 3.80505e-06 5.5313e-06 1.39375e-21 9.41782e-22 2.52969e-08"/>
              <!-- Part xl330_14 -->
              <geom type="mesh" class="visual" pos="-3.81639e-17 0.042 0.0145" quat="0.5 -0.5 -0.5 -0.5" mesh="xl330" material="xl330_material"/>
              <!-- Part leg_plate_7 -->
              <geom type="mesh" class="visual" pos="0.01 -0.0432 -0.0455" quat="0.707107 0.707107 0 9.13402e-17" mesh="leg_plate" material="leg_plate_material"/>
              <!-- Part leg_plate_8 -->
              <geom type="mesh" class="visual" pos="-0.01 -0.0432 0.0745" quat="1.66873e-16 6.14849e-17 -0.707107 0.707107" mesh="leg_plate" material="leg_plate_material"/>
              <!-- Link foot_2 -->
              <body name="foot_2" pos="-4.51028e-17 0.042 0.029" quat="1.23891e-18 1 4.33681e-19 1.32264e-16">
                <!-- Joint from xl330_3 to foot_2 -->
                <joint axis="0 0 1" name="right_ankle" type="hinge" range="-1.5707963267948966 1.5707963267948966" class="chosen_actuator"/>
                <inertial pos="0.00535915 -0.0128708 0.0145" mass="0.0227748" fullinertia="2.77519e-06 6.82595e-06 5.4299e-06 2.22912e-08 -3.15968e-12 -1.93034e-11"/>
                <!-- Part foot_2 -->
                <geom type="mesh" class="visual" pos="0.01 0.1272 0.0745" quat="0.707107 -0.707107 -0 3.06659e-19" mesh="foot" material="foot_material"/>
                <geom name="right_foot_collision" type="mesh" class="collision" pos="0.01 0.1272 0.0745" quat="0.707107 -0.707107 -0 3.06659e-19" mesh="foot" material="foot_material"/>
                <!-- Frame right_foot -->
                <site group="3" name="right_foot" pos="0.00549715 -0.021 0.0145" quat="0.707107 -0.707107 -0 3.06659e-19"/>
              </body>
            </body>
          </body>
        </body>
      </body>
    </body>
  </worldbody>
  <asset>
    <mesh file="left_roll_to_pitch.stl"/>
    <mesh file="head_pitch_to_yaw.stl"/>
    <mesh file="roll_motor_bottom.stl"/>
    <mesh file="foot.stl"/>
    <mesh file="roll_motor_top.stl"/>
    <mesh file="trunk.stl"/>
    <mesh file="head_yaw_to_roll.stl"/>
    <mesh file="xl330.stl"/>
    <mesh file="head_base_plate.stl"/>
    <mesh file="right_roll_to_pitch.stl"/>
    <mesh file="leg_plate.stl"/>
    <mesh file="neck_plate.stl"/>
    <mesh file="bearing.stl"/>
    <material name="xl330_material" rgba="0.286275 0.286275 0.286275 1"/>
    <material name="bearing_material" rgba="0.701961 0.701961 0.701961 1"/>
    <material name="trunk_material" rgba="0.235294 0.235294 0.235294 1"/>
    <material name="roll_motor_bottom_material" rgba="0.235294 0.235294 0.235294 1"/>
    <material name="roll_motor_top_material" rgba="0.235294 0.235294 0.235294 1"/>
    <material name="left_roll_to_pitch_material" rgba="0.235294 0.235294 0.235294 1"/>
    <material name="leg_plate_material" rgba="0.235294 0.235294 0.235294 1"/>
    <material name="foot_material" rgba="1 0.756863 0.054902 1"/>
    <material name="neck_plate_material" rgba="0.235294 0.235294 0.235294 1"/>
    <material name="head_pitch_to_yaw_material" rgba="0.235294 0.235294 0.235294 1"/>
    <material name="head_yaw_to_roll_material" rgba="0.235294 0.235294 0.235294 1"/>
    <material name="head_base_plate_material" rgba="0.235294 0.235294 0.235294 1"/>
    <material name="right_roll_to_pitch_material" rgba="0.235294 0.235294 0.235294 1"/>
  </asset>
  <actuator>
    <position class="chosen_actuator" name="left_hip_yaw" joint="left_hip_yaw" inheritrange="1"/>
    <position class="chosen_actuator" name="left_hip_roll" joint="left_hip_roll" inheritrange="1"/>
    <position class="chosen_actuator" name="left_hip_pitch" joint="left_hip_pitch" inheritrange="1"/>
    <position class="chosen_actuator" name="left_knee" joint="left_knee" inheritrange="1"/>
    <position class="chosen_actuator" name="left_ankle" joint="left_ankle" inheritrange="1"/>
    <position class="chosen_actuator" name="neck_pitch" joint="neck_pitch" inheritrange="1"/>
    <position class="chosen_actuator" name="head_pitch" joint="head_pitch" inheritrange="1"/>
    <position class="chosen_actuator" name="head_yaw" joint="head_yaw" inheritrange="1"/>
    <position class="chosen_actuator" name="head_roll" joint="head_roll" inheritrange="1"/>
    <position class="chosen_actuator" name="right_hip_yaw" joint="right_hip_yaw" inheritrange="1"/>
    <position class="chosen_actuator" name="right_hip_roll" joint="right_hip_roll" inheritrange="1"/>
    <position class="chosen_actuator" name="right_hip_pitch" joint="right_hip_pitch" inheritrange="1"/>
    <position class="chosen_actuator" name="right_knee" joint="right_knee" inheritrange="1"/>
    <position class="chosen_actuator" name="right_ankle" joint="right_ankle" inheritrange="1"/>
  </actuator>
  <equality/>
</mujoco>
