<?xml version="1.0" ?>
<!-- Generated using onshape-to-robot -->
<!-- Onshape https://cad.onshape.com/documents/804927696f06d877f3f1803e/w/3df6f6a8dcea50fb5658e3c0/e/eee1ab796d84f4ff324d3a02 -->
<mujoco model="microduck">
  <compiler angle="radian" meshdir="assets" autolimits="true"/>
  <default>
    <default class="microduck">
      <joint frictionloss="0.1" armature="0.005"/>
      <position kp="50" dampratio="1"/>
      <default class="visual">
        <geom type="mesh" contype="0" conaffinity="0" group="2"/>
      </default>
      <default class="collision">
        <geom group="3"/>
      </default>
    </default>
  </default>
  <!-- Additional joints_properties.xml -->
  <default>
    <default class="perfect_actuator">
      <geom contype="0" conaffinity="0"/>
      <joint damping="0.15" frictionloss="0.1" armature="0.001"/>
      <position kp="10.0" kv="0.1" forcerange="-20.0 20.0"/>
    </default>
    <default class="chosen_actuator">
      <geom contype="0" conaffinity="0"/>
      <joint damping="0.048" frictionloss="0.006" armature="0.002"/>
      <position kp="0.52" kv="0.0" forcerange="-0.91 0.91" ctrlrange="-10.0 10.0"/>
    </default>
  </default>
  <!-- Additional sensors.xml -->
  <sensor>
    <framequat name="orientation" objtype="site" noise="0.001" objname="imu"/>
    <gyro name="angular-velocity" site="imu" noise="0.005"/>
    <gyro name="imu_ang_vel" site="imu"/>
    <velocimeter name="imu_lin_vel" site="imu"/>
    <accelerometer name="imu_accel" site="imu"/>
    <subtreeangmom name="root_angmom" body="trunk_base"/>
  </sensor>
  <!-- Additional additional.xml -->
  <default>
    <default class="self_collision_only">
      <geom group="3" contype="2" conaffinity="2"/>
    </default>
  </default>
  <worldbody>
    <!-- Link trunk_base -->
    <body name="trunk_base" pos="0 0 0.12" quat="1 0 0 0" childclass="microduck">
      <freejoint name="trunk_base_freejoint"/>
      <inertial pos="-0.0141125 -0.000111648 0.0198336" mass="0.385924" fullinertia="0.000464287 0.000556195 0.000395643 6.35835e-08 -2.47128e-05 4.24564e-07"/>
      <!-- Part cell -->
      <geom type="mesh" class="visual" pos="-0.0263454 0.00899934 -0.0228" quat="1 2.498e-16 0 -4.44089e-16" mesh="cell" material="cell_material"/>
      <!-- Part xl330 -->
      <geom type="mesh" class="visual" pos="0.0125202 -0.02 0.0353" quat="1.04938e-25 -0.707107 0 -0.707107" mesh="xl330" material="xl330_material"/>
      <!-- Part bms -->
      <geom type="mesh" class="visual" pos="-0.0398454 0.0620566 -0.00623206" quat="0.707107 1.48021e-15 -0.707107 8.4992e-16" mesh="bms" material="bms_material"/>
      <!-- Part uc_boards -->
      <geom type="mesh" class="visual" pos="0.0125202 1.1237e-17 0.0351" quat="1 -9.77044e-18 -3.81639e-16 5.45638e-17" mesh="uc_boards" material="uc_boards_material"/>
      <!-- Part bottom_shell -->
      <geom type="mesh" class="visual" pos="0.0125202 -5.3936e-17 0.0352" quat="1 -2.91322e-17 -1.66533e-16 1.11019e-16" mesh="bottom_shell" material="bottom_shell_material"/>
      <geom type="mesh" class="self_collision_only" pos="0.0125202 -5.3936e-17 0.0352" quat="1 -2.91322e-17 -1.66533e-16 1.11019e-16" mesh="bottom_shell" material="bottom_shell_material"/>
      <!-- Part usb_c_charger -->
      <geom type="mesh" class="visual" pos="-0.0261798 0.01855 -0.01105" quat="0.5 -0.5 0.5 0.5" mesh="usb_c_charger" material="usb_c_charger_material"/>
      <!-- Part bearing -->
      <geom type="mesh" class="visual" pos="0.0125202 -0.04 0.0352" quat="1 0 0 0" mesh="bearing" material="bearing_material"/>
      <!-- Part trunk_yaw -->
      <geom type="mesh" class="visual" pos="0.0125202 7.42282e-19 0.0352" quat="1 0 9.10264e-17 -1.2793e-16" mesh="trunk_yaw" material="trunk_yaw_material"/>
      <!-- Part jumper -->
      <geom type="mesh" class="visual" pos="0.0149458 -0.232101 0.0567" quat="0.707107 4.85911e-16 3.33067e-16 -0.707107" mesh="jumper" material="jumper_material"/>
      <!-- Part holder -->
      <geom type="mesh" class="visual" pos="-0.0388454 -0.0645251 0.00914152" quat="0.707107 -7.39961e-17 0.707107 1.15088e-16" mesh="holder" material="holder_material"/>
      <!-- Part bno055 -->
      <geom type="mesh" class="visual" pos="-0.0284798 0.0225 0.0581" quat="3.77047e-16 0.707107 0.707107 3.29495e-16" mesh="bno055" material="bno055_material"/>
      <!-- Part xl330_2 -->
      <geom type="mesh" class="visual" pos="0.0125202 0.02 0.0353" quat="4.2008e-17 -0.707107 -0 -0.707107" mesh="xl330" material="xl330_material"/>
      <!-- Part top_shell -->
      <geom type="mesh" class="visual" pos="0.0124202 -5.40217e-17 0.0352" quat="1 -1.35064e-17 -3.46945e-16 1.29424e-16" mesh="top_shell" material="top_shell_material"/>
      <!-- Part xl330_3 -->
      <geom type="mesh" class="visual" pos="0.0375202 0.0001 0.0552" quat="0.707107 2.22045e-16 -2.22045e-16 0.707107" mesh="xl330" material="xl330_material"/>
      <!-- Part uc_inside_holder -->
      <geom type="mesh" class="visual" pos="0.00935462 0.000949336 0.035" quat="1 5.36693e-17 -9.78384e-16 7.02271e-16" mesh="uc_inside_holder" material="uc_inside_holder_material"/>
      <!-- Part raspberrypizerow -->
      <geom type="mesh" class="visual" pos="0.00299522 -2.5e-05 0.0533" quat="0.5 0.5 -0.5 -0.5" mesh="raspberrypizerow" material="raspberrypizerow_material"/>
      <!-- Part bearing_2 -->
      <geom type="mesh" class="visual" pos="0.0125202 -1.56125e-17 0.0352" quat="1 0 0 0" mesh="bearing" material="bearing_material"/>
      <!-- Part jack -->
      <geom type="mesh" class="visual" pos="-0.00792308 -0.182013 0.0567" quat="0.707107 0 2.42861e-17 -0.707107" mesh="jack" material="jack_material"/>
      <!-- Part board -->
      <geom type="mesh" class="visual" pos="-0.0479798 0.00949999 0.0567" quat="0.707107 7.06542e-16 -2.22045e-16 -0.707107" mesh="board" material="board_material"/>
      <!-- Part trunk_base -->
      <geom type="mesh" class="visual" pos="0.0125202 9.59122e-19 0.0352" quat="1 0 9.20949e-17 -1.27163e-16" mesh="trunk_base" material="trunk_base_material"/>
      <!-- Part power_switch -->
      <geom type="mesh" class="visual" pos="-0.0423998 0.0318 0.017165" quat="0.707107 -5.63935e-17 -0.707107 -3.33067e-16" mesh="power_switch" material="power_switch_material"/>
      <!-- Part cell_2 -->
      <geom type="mesh" class="visual" pos="-0.0263454 -0.0110007 -0.0228" quat="1 2.64273e-16 1.11022e-16 -2.51881e-16" mesh="cell" material="cell_material"/>
      <!-- Part power_switch_2 -->
      <geom type="mesh" class="visual" pos="-0.0423998 -0.0318 0.017165" quat="0.707107 -1.58596e-17 -0.707107 -5.15055e-17" mesh="power_switch" material="power_switch_material"/>
      <!-- Part uc -->
      <geom type="mesh" class="visual" pos="0.0125202 0 0.0351" quat="1 0 1.04558e-16 3.73317e-17" mesh="uc" material="uc_material"/>
      <!-- Frame imu -->
      <site group="3" name="imu" pos="-0.0284798 0.0227226 0.0581" quat="1 -2.07971e-17 -3.60822e-16 -8.10486e-17"/>
      <!-- Link roll_motor_bottom -->
      <body name="roll_motor_bottom" pos="0.0125202 0.02 0.0208" quat="1.10148e-17 0.707107 -0.707107 -9.50309e-17">
        <!-- Joint from trunk_base to roll_motor_bottom -->
        <joint axis="0 0 1" name="left_hip_yaw" type="hinge" range="-0.5235987755982988 0.5235987755982988" class="chosen_actuator"/>
        <inertial pos="-2.06207e-17 -0.000237525 0.0207938" mass="0.0252944" fullinertia="5.67885e-06 5.1295e-06 2.4759e-06 2.90165e-22 -9.78747e-22 -2.1555e-08"/>
        <!-- Part roll_motor_bottom -->
        <geom type="mesh" class="visual" pos="0.02 -5e-05 -0.0146" quat="4.59636e-17 0.707107 -0.707107 -2.11092e-16" mesh="roll_motor_bottom" material="roll_motor_bottom_material"/>
        <!-- Part roll_motor_top -->
        <geom type="mesh" class="visual" pos="0.02 0 -0.0146" quat="7.25743e-17 0.707107 -0.707107 -1.20793e-16" mesh="roll_motor_top" material="roll_motor_top_material"/>
        <!-- Part xl330_4 -->
        <geom type="mesh" class="visual" pos="-1.38778e-17 -5e-05 0.0286" quat="0.707107 1.28342e-16 -0 0.707107" mesh="xl330" material="xl330_material"/>
        <!-- Link left_roll_to_pitch -->
        <body name="left_roll_to_pitch" pos="-1.73472e-17 -0.01455 0.0286" quat="8.40463e-17 2.39753e-18 -0.707107 0.707107">
          <!-- Joint from roll_motor_bottom to left_roll_to_pitch -->
          <joint axis="0 0 1" name="left_hip_roll" type="hinge" range="-0.6981317007977318 0.6981317007977318" class="chosen_actuator"/>
          <inertial pos="0.034947 0.00019824 -0.0134625" mass="0.0304845" fullinertia="5.39431e-06 9.58888e-06 6.71172e-06 9.64608e-08 -4.86513e-08 2.08504e-08"/>
          <!-- Part left_roll_to_pitch -->
          <geom type="mesh" class="visual" pos="-0.02 0.0432 -0.0145" quat="0.5 -0.5 -0.5 -0.5" mesh="left_roll_to_pitch" material="left_roll_to_pitch_material"/>
          <!-- Part xl330_5 -->
          <geom type="mesh" class="visual" pos="0.0399 1.38778e-17 -0.0245" quat="1.26119e-16 1.05912e-17 -1 1.99089e-16" mesh="xl330" material="xl330_material"/>
          <!-- Link leg_plate -->
          <body name="leg_plate" pos="0.0544 1.47451e-17 -0.0245" quat="0.5 0.5 0.5 0.5">
            <!-- Joint from left_roll_to_pitch to leg_plate -->
            <joint axis="0 0 1" name="left_hip_pitch" type="hinge" range="-5.329070518200751e-15 1.5707963267948912" class="chosen_actuator"/>
            <inertial pos="-0.0297714 -2.02631e-16 -0.0142481" mass="0.0243882" fullinertia="3.34584e-06 6.61117e-06 5.2143e-06 -5.47406e-21 1.98369e-08 -3.42327e-14"/>
            <!-- Part leg_plate -->
            <geom type="mesh" class="visual" pos="0.0432 -0.01 0.0455" quat="0.5 -0.5 0.5 -0.5" mesh="leg_plate" material="leg_plate_material"/>
            <geom type="mesh" class="self_collision_only" pos="0.0432 -0.01 0.0455" quat="0.5 -0.5 0.5 -0.5" mesh="leg_plate" material="leg_plate_material"/>
            <!-- Part leg_plate_2 -->
            <geom type="mesh" class="visual" pos="0.0432 0.01 -0.0745" quat="0.5 0.5 0.5 0.5" mesh="leg_plate" material="leg_plate_material"/>
            <geom type="mesh" class="self_collision_only" pos="0.0432 0.01 -0.0745" quat="0.5 0.5 0.5 0.5" mesh="leg_plate" material="leg_plate_material"/>
            <!-- Part xl330_6 -->
            <geom type="mesh" class="visual" pos="-0.042 -1.63931e-16 -0.0145" quat="4.11478e-15 0.707107 -2.88658e-15 -0.707107" mesh="xl330" material="xl330_material"/>
            <!-- Link leg_plate_2 -->
            <body name="leg_plate_2" pos="-0.042 1.25334e-16 -2.35922e-16" quat="0.707107 -8.88623e-16 -6.10623e-15 -0.707107">
              <!-- Joint from leg_plate to leg_plate_2 -->
              <joint axis="0 0 1" name="left_knee" type="hinge" range="-1.9198621771937625 -0.0" class="chosen_actuator"/>
              <inertial pos="5.20864e-16 -0.0297714 -0.0142481" mass="0.0243882" fullinertia="6.61117e-06 3.34584e-06 5.2143e-06 3.59952e-20 3.42328e-14 1.98369e-08"/>
              <!-- Part leg_plate_3 -->
              <geom type="mesh" class="visual" pos="-0.01 0.0432 -0.0745" quat="1.55764e-15 8.63796e-15 -0.707107 -0.707107" mesh="leg_plate" material="leg_plate_material"/>
              <geom type="mesh" class="self_collision_only" pos="-0.01 0.0432 -0.0745" quat="1.55764e-15 8.63796e-15 -0.707107 -0.707107" mesh="leg_plate" material="leg_plate_material"/>
              <!-- Part leg_plate_4 -->
              <geom type="mesh" class="visual" pos="0.01 0.0432 0.0455" quat="0.707107 -0.707107 -8.21565e-15 1.8648e-15" mesh="leg_plate" material="leg_plate_material"/>
              <geom type="mesh" class="self_collision_only" pos="0.01 0.0432 0.0455" quat="0.707107 -0.707107 -8.21565e-15 1.8648e-15" mesh="leg_plate" material="leg_plate_material"/>
              <!-- Part xl330_7 -->
              <geom type="mesh" class="visual" pos="7.34655e-16 -0.042 -0.0145" quat="0.5 0.5 0.5 -0.5" mesh="xl330" material="xl330_material"/>
              <!-- Link foot_tpu_bottom -->
              <body name="foot_tpu_bottom" pos="7.32053e-16 -0.042 6.52256e-16" quat="2.93797e-15 4.89703e-15 -3.66374e-15 -1">
                <!-- Joint from leg_plate_2 to foot_tpu_bottom -->
                <joint axis="0 0 1" name="left_ankle" type="hinge" range="-1.5707963267949054 1.5707963267948877" class="chosen_actuator"/>
                <inertial pos="0.00475212 0.0143399 -0.0145" mass="0.0190505" fullinertia="3.25184e-06 6.82459e-06 4.90623e-06 -9.55165e-08 -2.23326e-11 -8.15886e-12"/>
                <!-- Part foot -->
                <geom type="mesh" class="visual" pos="0.01 -0.1272 -0.0745" quat="0.707107 0.707107 0 -4.46802e-31" mesh="foot" material="foot_material"/>
                <!-- Part foot_tpu_bottom -->
                <geom type="mesh" class="visual" pos="0.01 -0.1272 -0.0745" quat="0.707107 0.707107 -0 -1.20902e-18" mesh="foot_tpu_bottom" material="foot_tpu_bottom_material"/>
                <geom type="mesh" name="left_foot_collision" class="collision" pos="0.01 -0.1272 -0.0745" quat="0.707107 0.707107 -0 -1.20902e-18" mesh="foot_tpu_bottom" material="foot_tpu_bottom_material"/>
                <!-- Frame left_foot -->
                <site group="3" name="left_foot" pos="0.0048 0.021 -0.0145" quat="0.707107 0.707107 -0 -1.20902e-18"/>
              </body>
            </body>
          </body>
        </body>
      </body>
      <!-- Link long_neck_plate2 -->
      <body name="long_neck_plate2" pos="0.0375202 0.0146 0.0552" quat="9.7553e-17 -0 0.707107 0.707107">
        <!-- Joint from trunk_base to long_neck_plate2 -->
        <joint axis="0 0 1" name="neck_pitch" type="hinge" range="-1.2217304763960306 2.0943951023931953" class="chosen_actuator"/>
        <inertial pos="-0.000906124 0.0428312 -0.0147016" mass="0.0304826" fullinertia="1.19433e-05 4.60094e-06 9.75412e-06 -5.05283e-07 5.56736e-09 5.01905e-08"/>
        <!-- Part long_neck_plate1 -->
        <geom type="mesh" class="visual" pos="0.025 -0.02 -0.0145" quat="2.37191e-17 -7.76058e-17 -0.707107 -0.707107" mesh="long_neck_plate1" material="long_neck_plate1_material"/>
        <!-- Part neck_reinforcement -->
        <geom type="mesh" class="visual" pos="0.025 -0.02 -0.0145" quat="3.4416e-16 2.35902e-16 -0.707107 -0.707107" mesh="neck_reinforcement" material="neck_reinforcement_material"/>
        <!-- Part long_neck_plate2 -->
        <geom type="mesh" class="visual" pos="0.025 -0.02 -0.0145" quat="1.16601e-16 -3.38981e-17 -0.707107 -0.707107" mesh="long_neck_plate2" material="long_neck_plate2_material"/>
        <!-- Part xl330_8 -->
        <geom type="mesh" class="visual" pos="8.32667e-17 0.06 -0.0145" quat="0.5 -0.5 -0.5 -0.5" mesh="xl330" material="xl330_material"/>
        <!-- Link head_pitch_to_yaw -->
        <body name="head_pitch_to_yaw" pos="8.32667e-17 0.06 2.08167e-16" quat="1 2.51409e-16 -5.55112e-17 9.62329e-17">
          <!-- Joint from long_neck_plate2 to head_pitch_to_yaw -->
          <joint axis="0 0 1" name="head_pitch" type="hinge" range="-1.2217304763960457 1.2217304763960155" class="chosen_actuator"/>
          <inertial pos="0.00612022 0.0212216 -0.0145" mass="0.00847041" fullinertia="3.01296e-06 1.50757e-06 2.61412e-06 -4.42309e-07 -1.0103e-12 2.76775e-13"/>
          <!-- Part head_pitch_to_yaw -->
          <geom type="mesh" class="visual" pos="0.025 -0.08 -0.0145" quat="4.62469e-15 4.86729e-15 -0.707107 -0.707107" mesh="head_pitch_to_yaw" material="head_pitch_to_yaw_material"/>
          <!-- Link head_yaw_to_roll -->
          <body name="head_yaw_to_roll" pos="2.77556e-17 0.0465 -0.0145" quat="4.82426e-15 -4.86729e-15 0.707107 -0.707107">
            <!-- Joint from head_pitch_to_yaw to head_yaw_to_roll -->
            <joint axis="0 0 1" name="head_yaw" type="hinge" range="-2.6179938779915104 2.6179938779914784" class="chosen_actuator"/>
            <inertial pos="0.00569587 7.69891e-17 0.0184874" mass="0.0379676" fullinertia="7.59409e-06 1.62671e-05 1.68278e-05 -1.39627e-19 1.16448e-06 2.00203e-20"/>
            <!-- Part head_yaw_to_roll -->
            <geom type="mesh" class="visual" pos="-0.025 -4.22812e-16 0.1265" quat="1.12104e-44 -1 -8.02422e-15 4.65428e-29" mesh="head_yaw_to_roll" material="head_yaw_to_roll_material"/>
            <!-- Part xl330_9 -->
            <geom type="mesh" class="visual" pos="0 -2.52077e-18 0.0145" quat="5.67398e-15 0.707107 5.66214e-15 -0.707107" mesh="xl330" material="xl330_material"/>
            <!-- Link head_base_plate -->
            <body name="head_base_plate" pos="0.0305 4.67874e-16 0.0145" quat="0.5 -0.5 0.5 -0.5">
              <!-- Joint from head_yaw_to_roll to head_base_plate -->
              <joint axis="0 0 1" name="head_roll" type="hinge" range="-0.5235987755983406 0.5235987755982571" class="chosen_actuator"/>
              <inertial pos="0.00144117 -0.0024137 -0.0268186" mass="0.130459" fullinertia="0.00028915 0.00031562 7.26073e-05 -1.88182e-07 -7.6868e-06 1.7006e-06"/>
              <!-- Part xl330_10 -->
              <geom type="mesh" class="visual" pos="-1.29446e-15 0.009 -0.0791" quat="1.47949e-14 1.49123e-14 -0.707107 -0.707107" mesh="xl330" material="xl330_material"/>
              <!-- Part camera_spacer -->
              <geom type="mesh" class="visual" pos="4.7798e-15 -0.112 -0.0556" quat="0.5 -0.5 -0.5 -0.5" mesh="camera_spacer" material="camera_spacer_material"/>
              <!-- Part xl330_11 -->
              <geom type="mesh" class="visual" pos="7.17688e-16 4.16334e-16 0.0145" quat="1.46975e-14 0.707107 1.4877e-14 -0.707107" mesh="xl330" material="xl330_material"/>
              <!-- Part bearing_3 -->
              <geom type="mesh" class="visual" pos="-0.02 -1.33227e-15 -0.1215" quat="7.74004e-15 0.707107 0.707107 -7.4964e-15" mesh="bearing" material="bearing_material"/>
              <!-- Part head_top -->
              <geom type="mesh" class="visual" pos="5.85416e-15 -0.112 -0.0556" quat="0.5 -0.5 -0.5 -0.5" mesh="head_top" material="head_top_material"/>
              <!-- Part head_base_plate -->
              <geom type="mesh" class="visual" pos="5.08358e-15 -0.112 -0.0556" quat="0.5 -0.5 -0.5 -0.5" mesh="head_base_plate" material="head_base_plate_material"/>
              <!-- Part teeth -->
              <geom type="mesh" class="visual" pos="-2.5038e-15 0.07 -0.0556167" quat="0.5 0.5 -0.5 0.5" mesh="teeth" material="teeth_material"/>
              <!-- Frame mouth_tip -->
              <site group="3" name="mouth_tip" pos="1.12459e-15 -0.0175 0.0364" quat="0.5 -0.5 -0.5 -0.5"/>
              <!-- Link mouth -->
              <body name="mouth" pos="-0.04 -0.0175 -0.0261" quat="1.10176e-14 -0.707107 -1.85407e-14 -0.707107">
                <!-- Joint from head_base_plate to mouth -->
                <!-- Joint is "fixed", skipping it -->
                <inertial pos="0.0362182 0.00480827 0.04" mass="0.0177152" fullinertia="1.33164e-05 1.88861e-05 6.3965e-06 -8.59363e-07 -5.81365e-13 7.1662e-14"/>
                <!-- Part mouth -->
                <geom type="mesh" class="visual" pos="-0.0295 0.0945 0.04" quat="0.707107 0.707107 3.77476e-15 3.83691e-15" mesh="mouth" material="mouth_material"/>
                <!-- Part teeth_2 -->
                <geom type="mesh" class="visual" pos="-0.0295339 0.0945 0.04" quat="0.707107 0.707107 3.66374e-15 3.83691e-15" mesh="teeth" material="teeth_material"/>
              </body>
              <!-- Link camshaft -->
              <body name="camshaft" pos="-0.0145 0.009 -0.0791" quat="1.48509e-14 -0.707107 -1.4766e-14 -0.707107">
                <!-- Joint from head_base_plate to camshaft -->
                <!-- Joint is "fixed", skipping it -->
                <inertial pos="-0.00449882 -0.00260595 0.0145" mass="0.00410844" fullinertia="1.13143e-06 1.20303e-06 4.65564e-07 -1.37479e-07 -9.03834e-16 -3.78976e-16"/>
                <!-- Part camshaft -->
                <geom type="mesh" class="visual" pos="0.0235 0.121 0.0145" quat="0.707107 0.707107 -0 -6.13094e-17" mesh="camshaft" material="camshaft_material"/>
                <!-- Link crossmember -->
                <body name="crossmember" pos="0.00248141 0.00968724 -0.005" quat="4.8483e-19 1 8.67362e-19 -8.75719e-17">
                  <!-- Joint from camshaft to crossmember -->
                  <!-- Joint is "fixed", skipping it -->
                  <inertial pos="0.0265632 0.0102418 -0.0195" mass="0.00868921" fullinertia="8.12821e-06 8.35559e-06 1.78782e-06 -4.75971e-07 -1.57804e-13 8.67372e-13"/>
                  <!-- Part crossmember -->
                  <geom type="mesh" class="visual" pos="0.0210186 -0.111313 -0.0195" quat="0.707107 -0.707107 0 -2.72368e-31" mesh="crossmember" material="crossmember_material"/>
                  <!-- Link mouth_2 -->
                  <body name="mouth_2" pos="0.043041 0.00373183 0.0205" quat="0 1 0 0">
                    <!-- Joint from crossmember to mouth_2 -->
                    <!-- Joint is "fixed", skipping it -->
                    <inertial pos="0.0436958 0.0253529 0.04" mass="0.0177152" fullinertia="1.33164e-05 1.88861e-05 6.3965e-06 -8.59363e-07 -5.81365e-13 7.1662e-14"/>
                    <!-- Part mouth_2 -->
                    <geom type="mesh" class="visual" pos="-0.0220224 0.115045 0.04" quat="0.707107 0.707107 0 4.16995e-26" mesh="mouth" material="mouth_material"/>
                    <!-- Part teeth_3 -->
                    <geom type="mesh" class="visual" pos="-0.0220563 0.115045 0.04" quat="0.707107 0.707107 0 1.55949e-28" mesh="teeth" material="teeth_material"/>
                  </body>
                </body>
              </body>
            </body>
          </body>
        </body>
      </body>
      <!-- Link xl330 -->
      <body name="xl330" pos="0.0125202 -0.02 0.0208" quat="5.94083e-17 -1 -1.94289e-15 5.39815e-15">
        <!-- Joint from trunk_base to xl330 -->
        <joint axis="0 0 1" name="right_hip_yaw" type="hinge" range="-0.5235987755983024 0.5235987755982953" class="chosen_actuator"/>
        <inertial pos="0.000237525 1.89193e-17 0.0207938" mass="0.0252944" fullinertia="5.1295e-06 5.67885e-06 2.4759e-06 5.93018e-22 2.1555e-08 -6.18119e-21"/>
        <!-- Part roll_motor_top_2 -->
        <geom type="mesh" class="visual" pos="0 0.02 -0.0146" quat="8.03113e-17 1 3.69779e-32 -0" mesh="roll_motor_top" material="roll_motor_top_material"/>
        <!-- Part roll_motor_bottom_2 -->
        <geom type="mesh" class="visual" pos="5e-05 0.02 -0.0146" quat="8.03113e-17 1 -5.55112e-17 -9.03502e-17" mesh="roll_motor_bottom" material="roll_motor_bottom_material"/>
        <!-- Part xl330_12 -->
        <geom type="mesh" class="visual" pos="5e-05 3.1225e-17 0.0286" quat="5.55112e-17 6.13721e-17 1.11022e-16 1" mesh="xl330" material="xl330_material"/>
        <!-- Link right_roll_to_pitch -->
        <body name="right_roll_to_pitch" pos="0.01455 3.1225e-17 0.0286" quat="0.5 -0.5 0.5 -0.5">
          <!-- Joint from xl330 to right_roll_to_pitch -->
          <joint axis="0 0 1" name="right_hip_roll" type="hinge" range="-0.6981317007977318 0.6981317007977318" class="chosen_actuator"/>
          <inertial pos="-0.034947 0.00019824 -0.0134625" mass="0.0304845" fullinertia="5.39431e-06 9.58888e-06 6.71172e-06 -9.64608e-08 4.86513e-08 2.08504e-08"/>
          <!-- Part right_roll_to_pitch -->
          <geom type="mesh" class="visual" pos="0.02 0.0432 -0.0145" quat="0.5 -0.5 -0.5 -0.5" mesh="right_roll_to_pitch" material="right_roll_to_pitch_material"/>
          <!-- Part xl330_13 -->
          <geom type="mesh" class="visual" pos="-0.0399 1.47451e-17 -0.0245" quat="4.16334e-17 1 -8.71639e-17 1.38778e-16" mesh="xl330" material="xl330_material"/>
          <!-- Link xl330_2 -->
          <body name="xl330_2" pos="-0.0544 1.56125e-17 -0.0245" quat="0.5 0.5 -0.5 -0.5">
            <!-- Joint from right_roll_to_pitch to xl330_2 -->
            <joint axis="0 0 1" name="right_hip_pitch" type="hinge" range="-1.570796326794886 1.0658141036401503e-14" class="chosen_actuator"/>
            <inertial pos="0.0297714 3.49544e-16 -0.0142481" mass="0.0243882" fullinertia="3.34584e-06 6.61117e-06 5.2143e-06 -2.01658e-20 -1.98369e-08 3.42328e-14"/>
            <!-- Part xl330_14 -->
            <geom type="mesh" class="visual" pos="0.042 4.27609e-16 -0.0145" quat="0.707107 -2.96292e-15 0.707107 3.92126e-15" mesh="xl330" material="xl330_material"/>
            <!-- Part leg_plate_5 -->
            <geom type="mesh" class="visual" pos="-0.0432 0.01 0.0455" quat="0.5 -0.5 -0.5 0.5" mesh="leg_plate" material="leg_plate_material"/>
            <geom type="mesh" class="self_collision_only" pos="-0.0432 0.01 0.0455" quat="0.5 -0.5 -0.5 0.5" mesh="leg_plate" material="leg_plate_material"/>
            <!-- Part leg_plate_6 -->
            <geom type="mesh" class="visual" pos="-0.0432 -0.01 -0.0745" quat="0.5 0.5 -0.5 -0.5" mesh="leg_plate" material="leg_plate_material"/>
            <geom type="mesh" class="self_collision_only" pos="-0.0432 -0.01 -0.0745" quat="0.5 0.5 -0.5 -0.5" mesh="leg_plate" material="leg_plate_material"/>
            <!-- Link xl330_3 -->
            <body name="xl330_3" pos="0.042 4.41921e-16 -9.99201e-16" quat="0.707107 3.63597e-16 -5.13478e-16 0.707107">
              <!-- Joint from xl330_2 to xl330_3 -->
              <joint axis="0 0 1" name="right_knee" type="hinge" range="-6.217248937900877e-15 1.9198621771937563" class="chosen_actuator"/>
              <inertial pos="1.50126e-16 -0.0297714 -0.0142481" mass="0.0243882" fullinertia="6.61117e-06 3.34584e-06 5.2143e-06 -3.0481e-21 3.42328e-14 1.98369e-08"/>
              <!-- Part xl330_15 -->
              <geom type="mesh" class="visual" pos="1.53523e-16 -0.042 -0.0145" quat="0.5 0.5 0.5 -0.5" mesh="xl330" material="xl330_material"/>
              <!-- Part leg_plate_7 -->
              <geom type="mesh" class="visual" pos="0.01 0.0432 0.0455" quat="0.707107 -0.707107 1.33227e-15 1.95117e-15" mesh="leg_plate" material="leg_plate_material"/>
              <geom type="mesh" class="self_collision_only" pos="0.01 0.0432 0.0455" quat="0.707107 -0.707107 1.33227e-15 1.95117e-15" mesh="leg_plate" material="leg_plate_material"/>
              <!-- Part leg_plate_8 -->
              <geom type="mesh" class="visual" pos="-0.01 0.0432 -0.0745" quat="1.55046e-15 -9.41669e-16 -0.707107 -0.707107" mesh="leg_plate" material="leg_plate_material"/>
              <geom type="mesh" class="self_collision_only" pos="-0.01 0.0432 -0.0745" quat="1.55046e-15 -9.41669e-16 -0.707107 -0.707107" mesh="leg_plate" material="leg_plate_material"/>
              <!-- Link foot -->
              <body name="foot" pos="2.00361e-16 -0.042 -1.52656e-15" quat="1 2.34573e-16 2.69229e-15 4.52275e-16">
                <!-- Joint from xl330_3 to foot -->
                <joint axis="0 0 1" name="right_ankle" type="hinge" range="-1.5707963267948983 1.5707963267948948" class="chosen_actuator"/>
                <inertial pos="0.00475212 -0.0143399 -0.0145" mass="0.0190505" fullinertia="3.25184e-06 6.82459e-06 4.90623e-06 9.55165e-08 2.23326e-11 -8.15886e-12"/>
                <!-- Part foot_2 -->
                <geom type="mesh" class="visual" pos="0.01 0.1272 0.0455" quat="0.707107 -0.707107 0 1.2444e-33" mesh="foot" material="foot_material"/>
                <!-- Part foot_tpu_bottom_2 -->
                <geom type="mesh" class="visual" pos="0.01 0.1272 0.0455" quat="0.707107 -0.707107 -0 -2.19513e-30" mesh="foot_tpu_bottom" material="foot_tpu_bottom_material"/>
                <geom type="mesh" name="right_foot_collision" class="collision" pos="0.01 0.1272 0.0455" quat="0.707107 -0.707107 -0 -2.19513e-30" mesh="foot_tpu_bottom" material="foot_tpu_bottom_material"/>
                <!-- Frame right_foot -->
                <site group="3" name="right_foot" pos="0.0048 -0.021 -0.0145" quat="0.707107 -0.707107 -0 -2.19513e-30"/>
              </body>
            </body>
          </body>
        </body>
      </body>
    </body>
  </worldbody>
  <asset>
    <mesh file="trunk_yaw.stl"/>
    <mesh file="head_pitch_to_yaw.stl"/>
    <mesh file="foot.stl"/>
    <mesh file="head_base_plate.stl"/>
    <mesh file="crossmember.stl"/>
    <mesh file="uc_inside_holder.stl"/>
    <mesh file="foot_tpu_bottom.stl"/>
    <mesh file="usb_c_charger.stl"/>
    <mesh file="cell.stl"/>
    <mesh file="neck_reinforcement.stl"/>
    <mesh file="roll_motor_bottom.stl"/>
    <mesh file="bearing.stl"/>
    <mesh file="camera_spacer.stl"/>
    <mesh file="power_switch.stl"/>
    <mesh file="teeth.stl"/>
    <mesh file="camshaft.stl"/>
    <mesh file="holder.stl"/>
    <mesh file="head_top.stl"/>
    <mesh file="board.stl"/>
    <mesh file="raspberrypizerow.stl"/>
    <mesh file="left_roll_to_pitch.stl"/>
    <mesh file="xl330.stl"/>
    <mesh file="jumper.stl"/>
    <mesh file="right_roll_to_pitch.stl"/>
    <mesh file="long_neck_plate1.stl"/>
    <mesh file="leg_plate.stl"/>
    <mesh file="long_neck_plate2.stl"/>
    <mesh file="top_shell.stl"/>
    <mesh file="head_yaw_to_roll.stl"/>
    <mesh file="uc_boards.stl"/>
    <mesh file="bottom_shell.stl"/>
    <mesh file="roll_motor_top.stl"/>
    <mesh file="bno055.stl"/>
    <mesh file="trunk_base.stl"/>
    <mesh file="mouth.stl"/>
    <mesh file="bms.stl"/>
    <mesh file="jack.stl"/>
    <mesh file="uc.stl"/>
    <material name="cell_material" rgba="0.615686 0.811765 0.929412 1"/>
    <material name="xl330_material" rgba="0.286275 0.286275 0.286275 1"/>
    <material name="bms_material" rgba="0.231373 0.380392 0.705882 1"/>
    <material name="uc_boards_material" rgba="0.972549 0.529412 0.00392157 1"/>
    <material name="bottom_shell_material" rgba="0.6 0.6 0.6 1"/>
    <material name="usb_c_charger_material" rgba="0.615686 0.811765 0.929412 1"/>
    <material name="bearing_material" rgba="0.701961 0.701961 0.701961 1"/>
    <material name="trunk_yaw_material" rgba="0.235294 0.235294 0.235294 1"/>
    <material name="jumper_material" rgba="0.498039 0.498039 0.498039 1"/>
    <material name="holder_material" rgba="0.647059 0.647059 0.647059 1"/>
    <material name="bno055_material" rgba="0.615686 0.811765 0.929412 1"/>
    <material name="top_shell_material" rgba="0.6 0.6 0.6 1"/>
    <material name="uc_inside_holder_material" rgba="0.615686 0.811765 0.929412 1"/>
    <material name="raspberrypizerow_material" rgba="0.231373 0.380392 0.705882 1"/>
    <material name="jack_material" rgba="0.647059 0.647059 0.647059 1"/>
    <material name="board_material" rgba="0 0.501961 0 1"/>
    <material name="trunk_base_material" rgba="0.235294 0.235294 0.235294 1"/>
    <material name="power_switch_material" rgba="0.901961 0.901961 0.901961 1"/>
    <material name="uc_material" rgba="0.768627 0.886275 0.952941 1"/>
    <material name="roll_motor_bottom_material" rgba="0.235294 0.235294 0.235294 1"/>
    <material name="roll_motor_top_material" rgba="0.235294 0.235294 0.235294 1"/>
    <material name="left_roll_to_pitch_material" rgba="0.235294 0.235294 0.235294 1"/>
    <material name="leg_plate_material" rgba="0.235294 0.235294 0.235294 1"/>
    <material name="foot_material" rgba="1 0.756863 0.054902 1"/>
    <material name="foot_tpu_bottom_material" rgba="0.262745 0.262745 0.262745 1"/>
    <material name="long_neck_plate1_material" rgba="0.235294 0.235294 0.235294 1"/>
    <material name="neck_reinforcement_material" rgba="0.235294 0.235294 0.235294 1"/>
    <material name="long_neck_plate2_material" rgba="0.235294 0.235294 0.235294 1"/>
    <material name="head_pitch_to_yaw_material" rgba="0.235294 0.235294 0.235294 1"/>
    <material name="head_yaw_to_roll_material" rgba="0.235294 0.235294 0.235294 1"/>
    <material name="camera_spacer_material" rgba="0.917647 0.917647 0.917647 1"/>
    <material name="head_top_material" rgba="0.6 0.6 0.6 1"/>
    <material name="head_base_plate_material" rgba="0.235294 0.235294 0.235294 1"/>
    <material name="teeth_material" rgba="0.984314 0.984314 0.984314 1"/>
    <material name="mouth_material" rgba="0.235294 0.235294 0.235294 1"/>
    <material name="camshaft_material" rgba="0.498039 0.498039 0.498039 1"/>
    <material name="crossmember_material" rgba="0.980392 0.713725 0.00392157 1"/>
    <material name="right_roll_to_pitch_material" rgba="0.235294 0.235294 0.235294 1"/>
  </asset>
  <actuator>
    <position class="chosen_actuator" name="left_hip_yaw" joint="left_hip_yaw"/>
    <position class="chosen_actuator" name="left_hip_roll" joint="left_hip_roll"/>
    <position class="chosen_actuator" name="left_hip_pitch" joint="left_hip_pitch"/>
    <position class="chosen_actuator" name="left_knee" joint="left_knee"/>
    <position class="chosen_actuator" name="left_ankle" joint="left_ankle"/>
    <position class="chosen_actuator" name="neck_pitch" joint="neck_pitch"/>
    <position class="chosen_actuator" name="head_pitch" joint="head_pitch"/>
    <position class="chosen_actuator" name="head_yaw" joint="head_yaw"/>
    <position class="chosen_actuator" name="head_roll" joint="head_roll"/>
    <position class="chosen_actuator" name="right_hip_yaw" joint="right_hip_yaw"/>
    <position class="chosen_actuator" name="right_hip_roll" joint="right_hip_roll"/>
    <position class="chosen_actuator" name="right_hip_pitch" joint="right_hip_pitch"/>
    <position class="chosen_actuator" name="right_knee" joint="right_knee"/>
    <position class="chosen_actuator" name="right_ankle" joint="right_ankle"/>
  </actuator>
  <equality/>
</mujoco>
