<?xml version="1.0" ?>
<!-- Generated using onshape-to-robot -->
<!-- Onshape https://cad.onshape.com/documents/804927696f06d877f3f1803e/w/3df6f6a8dcea50fb5658e3c0/e/eee1ab796d84f4ff324d3a02 -->
<mujoco model="microduck">
  <compiler angle="radian" meshdir="assets" autolimits="true"/>
  <default>
    <default class="microduck">
      <joint frictionloss="0.1" armature="0.005"/>
      <position kp="50" dampratio="1"/>
      <default class="visual">
        <geom type="mesh" contype="0" conaffinity="0" group="2"/>
      </default>
      <default class="collision">
        <geom group="3"/>
      </default>
    </default>
  </default>
  <!-- Additional joints_properties.xml -->
  <default>
    <default class="perfect_actuator">
      <geom contype="0" conaffinity="0"/>
      <joint damping="0.15" frictionloss="0.1" armature="0.001"/>
      <position kp="10.0" kv="0.1" forcerange="-20.0 20.0"/>
    </default>
    <default class="xc330m288t">
      <!-- m1 -->
      <geom contype="0" conaffinity="0"/>
      <joint damping="0.035" frictionloss="0.021" armature="0.0017"/>
      <!-- kp 600 -->
      <!-- <position kp="0.97" kv="0.0" forcerange="-0.66 0.66"/> -->
      <!-- kp 400 -->
      <!-- <position kp="0.65" kv="0.0" forcerange="-0.66 0.66"/> -->
      <!-- kp 200 -->
      <position kp="0.32" kv="0.0" forcerange="-0.66 0.66"/>
      <default class="chosen_actuator"/>
    </default>
  </default>
  <!-- Additional sensors.xml -->
  <sensor>
    <framequat name="orientation" objtype="site" noise="0.001" objname="imu"/>
    <gyro name="angular-velocity" site="imu" noise="0.005"/>
    <gyro name="imu_ang_vel" site="imu"/>
    <velocimeter name="imu_lin_vel" site="imu"/>
    <subtreeangmom name="root_angmom" body="trunk_base"/>
  </sensor>
  <worldbody>
    <!-- Link trunk_base -->
    <body name="trunk_base" pos="0 0 0.12" quat="1 0 0 0" childclass="microduck">
      <freejoint name="trunk_base_freejoint"/>
      <inertial pos="-0.010876 -0.000476206 0.0189092" mass="0.307054" fullinertia="0.000306438 0.000406337 0.000265753 -1.68276e-06 -1.79498e-05 -1.57212e-07"/>
      <!-- Part ubec_8v_5v_dc_dc -->
      <geom type="mesh" class="visual" pos="-0.0418856 -0.0130219 0.00180235" quat="0.707107 -9.32242e-17 -0.707107 9.32242e-17" mesh="ubec_8v_5v_dc_dc" material="ubec_8v_5v_dc_dc_material"/>
      <!-- Part cell -->
      <geom type="mesh" class="visual" pos="-0.0263856 0.008 -0.0211976" quat="1 2.79648e-16 1.11022e-16 -3.60634e-16" mesh="cell" material="cell_material"/>
      <!-- Part xl330 -->
      <geom type="mesh" class="visual" pos="0.0125644 -0.02 0.0368" quat="3.63371e-40 -0.707107 -0 -0.707107" mesh="xl330" material="xl330_material"/>
      <!-- Part bms -->
      <geom type="mesh" class="visual" pos="-0.0388856 0.0610972 -0.0168297" quat="0.707107 -1.21183e-16 -0.707107 -1.22399e-16" mesh="bms" material="bms_material"/>
      <!-- Part usb_c_charger -->
      <geom type="mesh" class="visual" pos="-0.0288856 0.0185 -0.00945" quat="0.5 -0.5 0.5 0.5" mesh="usb_c_charger" material="usb_c_charger_material"/>
      <!-- Part bearing -->
      <geom type="mesh" class="visual" pos="0.0125644 -0.04 0.0367" quat="1 0 0 0" mesh="bearing" material="bearing_material"/>
      <!-- Part trunk_yaw -->
      <geom type="mesh" class="visual" pos="0.0125644 4.61201e-19 0.0367" quat="1 -0 9.96968e-17 -0" mesh="trunk_yaw" material="trunk_yaw_material"/>
      <!-- Part jumper -->
      <geom type="mesh" class="visual" pos="0.205953 0.0299255 0.0593" quat="1 0 -4.91999e-72 2.20758e-44" mesh="jumper" material="jumper_material"/>
      <!-- Part holder -->
      <geom type="mesh" class="visual" pos="-0.0388856 -0.0655245 0.0107439" quat="0.707107 0 0.707107 7.7893e-17" mesh="holder" material="holder_material"/>
      <!-- Part bno055 -->
      <geom type="mesh" class="visual" pos="-0.0486356 -0.0135 0.0607" quat="1.11022e-17 6.93889e-17 1 -0" mesh="bno055" material="bno055_material"/>
      <!-- Part xl330_2 -->
      <geom type="mesh" class="visual" pos="0.0125644 0.02 0.0368" quat="4.2008e-17 -0.707107 0 -0.707107" mesh="xl330" material="xl330_material"/>
      <!-- Part xl330_3 -->
      <geom type="mesh" class="visual" pos="0.0375644 0.0001 0.0537" quat="0.707107 2.77556e-16 0 0.707107" mesh="xl330" material="xl330_material"/>
      <!-- Part raspberrypizerow -->
      <geom type="mesh" class="visual" pos="-0.0261106 0.017975 0.0577" quat="3.38754e-17 -0 0.707107 0.707107" mesh="raspberrypizerow" material="raspberrypizerow_material"/>
      <!-- Part bearing_2 -->
      <geom type="mesh" class="visual" pos="0.0125644 -1.56125e-17 0.0367" quat="1 0 0 0" mesh="bearing" material="bearing_material"/>
      <!-- Part board -->
      <geom type="mesh" class="visual" pos="-0.0356476 -0.033 0.0593" quat="1 0 0 0" mesh="board" material="board_material"/>
      <!-- Part uc_boards -->
      <geom type="mesh" class="visual" pos="0.0125644 -7.71491e-18 0.0367" quat="1 -3.84016e-17 1.11022e-16 -5.52328e-17" mesh="uc_boards" material="uc_boards_material"/>
      <!-- Part trunk_base -->
      <geom type="mesh" class="visual" pos="0.0125644 6.78041e-19 0.0367" quat="1 -0 1.11022e-16 1.11022e-16" mesh="trunk_base" material="trunk_base_material"/>
      <!-- Part power_switch -->
      <geom type="mesh" class="visual" pos="-0.0423556 0.0318 0.016765" quat="0.707107 -0 -0.707107 -0" mesh="power_switch" material="power_switch_material"/>
      <!-- Part cell_2 -->
      <geom type="mesh" class="visual" pos="-0.0263856 -0.012 -0.0211976" quat="1 3.38412e-16 -1.11022e-16 -4.82905e-16" mesh="cell" material="cell_material"/>
      <!-- Part power_switch_2 -->
      <geom type="mesh" class="visual" pos="-0.0423556 -0.0318 0.016765" quat="0.707107 0 -0.707107 1.11022e-16" mesh="power_switch" material="power_switch_material"/>
      <!-- Part uc -->
      <geom type="mesh" class="visual" pos="0.0125644 0 0.0367" quat="1 -0 2.22045e-16 -0" mesh="uc" material="uc_material"/>
      <!-- Frame imu -->
      <site group="3" name="imu" pos="-0.0488583 -0.0135 0.0607" quat="1 0 1.11022e-16 -6.93889e-17"/>
      <!-- Link roll_motor_bottom -->
      <body name="roll_motor_bottom" pos="0.0125644 0.02 0.0223" quat="5.02268e-17 -0.707107 0.707107 1.56272e-16">
        <!-- Joint from trunk_base to roll_motor_bottom -->
        <joint axis="0 0 1" name="left_hip_yaw" type="hinge" range="-0.5235987755982988 0.5235987755982988" class="chosen_actuator"/>
        <inertial pos="2.79183e-16 -0.000237525 0.0207938" mass="0.0252944" fullinertia="5.67885e-06 5.1295e-06 2.4759e-06 2.67262e-22 -4.24779e-20 -2.1555e-08"/>
        <!-- Part roll_motor_bottom -->
        <geom type="mesh" class="visual" pos="0.02 -5e-05 -0.0146" quat="2.58346e-17 -0.707107 0.707107 1.29174e-16" mesh="roll_motor_bottom" material="roll_motor_bottom_material"/>
        <!-- Part roll_motor_top -->
        <geom type="mesh" class="visual" pos="0.02 -3.46945e-18 -0.0146" quat="3.80526e-17 0.707107 -0.707107 -6.52866e-17" mesh="roll_motor_top" material="roll_motor_top_material"/>
        <!-- Part xl330_4 -->
        <geom type="mesh" class="visual" pos="3.01842e-16 -5e-05 0.0286" quat="0.707107 9.8466e-17 -5.55112e-17 0.707107" mesh="xl330" material="xl330_material"/>
        <!-- Link left_roll_to_pitch -->
        <body name="left_roll_to_pitch" pos="3.08781e-16 -0.01455 0.0286" quat="4.2929e-17 -3.25767e-16 0.707107 -0.707107">
          <!-- Joint from roll_motor_bottom to left_roll_to_pitch -->
          <joint axis="0 0 1" name="left_hip_roll" type="hinge" range="-0.6981317007977362 0.6981317007977274" class="chosen_actuator"/>
          <inertial pos="0.0349455 0.000200457 -0.013468" mass="0.0304911" fullinertia="5.39923e-06 9.59277e-06 6.71214e-06 9.71011e-08 -5.00722e-08 2.24922e-08"/>
          <!-- Part left_roll_to_pitch -->
          <geom type="mesh" class="visual" pos="-0.02 0.0432 -0.0145" quat="0.5 -0.5 -0.5 -0.5" mesh="left_roll_to_pitch" material="left_roll_to_pitch_material"/>
          <!-- Part xl330_5 -->
          <geom type="mesh" class="visual" pos="0.0399 -1.91687e-16 -0.0245" quat="6.39154e-17 -8.09948e-18 -1 -1.12269e-16" mesh="xl330" material="xl330_material"/>
          <!-- Link leg_plate -->
          <body name="leg_plate" pos="0.0544 -1.91687e-16 -0.0245" quat="0.5 0.5 0.5 0.5">
            <!-- Joint from left_roll_to_pitch to leg_plate -->
            <joint axis="0 0 1" name="left_hip_pitch" type="hinge" range="-8.881784197001252e-16 1.5707963267948957" class="chosen_actuator"/>
            <inertial pos="-0.0289616 -4.65015e-17 -0.0142663" mass="0.0262855" fullinertia="3.72519e-06 7.24907e-06 5.52389e-06 3.45319e-21 2.48125e-08 5.91291e-21"/>
            <!-- Part leg_plate -->
            <geom type="mesh" class="visual" pos="0.0432 -0.01 0.0455" quat="0.5 -0.5 0.5 -0.5" mesh="leg_plate" material="leg_plate_material"/>
            <!-- Part leg_plate_2 -->
            <geom type="mesh" class="visual" pos="0.0432 0.01 -0.0745" quat="0.5 0.5 0.5 0.5" mesh="leg_plate" material="leg_plate_material"/>
            <!-- Part xl330_6 -->
            <geom type="mesh" class="visual" pos="-0.042 -2.21177e-17 -0.0145" quat="9.79387e-16 0.707107 -1.11022e-15 -0.707107" mesh="xl330" material="xl330_material"/>
            <!-- Link leg_plate_2 -->
            <body name="leg_plate_2" pos="-0.042 6.41848e-17 -5.55112e-17" quat="0.707107 -5.66479e-16 -1.33227e-15 -0.707107">
              <!-- Joint from leg_plate to leg_plate_2 -->
              <joint axis="0 0 1" name="left_knee" type="hinge" range="-1.9198621771937625 -0.0" class="chosen_actuator"/>
              <inertial pos="4.7031e-16 -0.0289616 -0.0142663" mass="0.0262855" fullinertia="7.24907e-06 3.72519e-06 5.52389e-06 3.98896e-20 2.6702e-20 2.48125e-08"/>
              <!-- Part leg_plate_3 -->
              <geom type="mesh" class="visual" pos="-0.01 0.0432 -0.0745" quat="3.13508e-15 5.25339e-15 -0.707107 -0.707107" mesh="leg_plate" material="leg_plate_material"/>
              <!-- Part leg_plate_4 -->
              <geom type="mesh" class="visual" pos="0.01 0.0432 0.0455" quat="0.707107 -0.707107 -4.77396e-15 2.98698e-15" mesh="leg_plate" material="leg_plate_material"/>
              <!-- Part xl330_7 -->
              <geom type="mesh" class="visual" pos="6.97359e-16 -0.042 -0.0145" quat="0.5 0.5 0.5 -0.5" mesh="xl330" material="xl330_material"/>
              <!-- Link foot_tpu_bottom -->
              <body name="foot_tpu_bottom" pos="7.07767e-16 -0.042 1.249e-16" quat="1.65443e-15 1.56827e-15 -8.88178e-16 -1">
                <!-- Joint from leg_plate_2 to foot_tpu_bottom -->
                <joint axis="0 0 1" name="left_ankle" type="hinge" range="-1.5707963267949054 1.5707963267948877" class="chosen_actuator"/>
                <inertial pos="0.00475212 0.0143399 -0.0145" mass="0.0190505" fullinertia="3.25184e-06 6.82459e-06 4.90623e-06 -9.55165e-08 -2.23326e-11 -8.15886e-12"/>
                <!-- Part foot -->
                <geom type="mesh" class="visual" pos="0.01 -0.1272 -0.0745" quat="0.707107 0.707107 0 1.56982e-32" mesh="foot" material="foot_material"/>
                <!-- Part foot_tpu_bottom -->
                <geom type="mesh" class="visual" pos="0.01 -0.1272 -0.0745" quat="0.707107 0.707107 0 2.46428e-28" mesh="foot_tpu_bottom" material="foot_tpu_bottom_material"/>
                <geom name="left_foot_collision" type="mesh" class="collision" pos="0.01 -0.1272 -0.0745" quat="0.707107 0.707107 0 2.46428e-28" mesh="foot_tpu_bottom" material="foot_tpu_bottom_material"/>
                <!-- Frame left_foot -->
                <site group="3" name="left_foot" pos="0.0048 0.021 -0.0145" quat="0.707107 0.707107 0 2.46428e-28"/>
              </body>
            </body>
          </body>
        </body>
      </body>
      <!-- Link neck_plate -->
      <body name="neck_plate" pos="0.0375644 0.0146 0.0537" quat="7.04962e-17 -1.66533e-16 -0.707107 -0.707107">
        <!-- Joint from trunk_base to neck_plate -->
        <joint axis="0 0 1" name="neck_pitch" type="hinge" range="-1.2217304763960315 1.2217304763960297" class="chosen_actuator"/>
        <inertial pos="-1.30185e-15 0.0296987 -0.0147301" mass="0.0266987" fullinertia="7.55113e-06 3.85092e-06 5.69714e-06 2.40895e-21 2.8555e-21 2.64276e-08"/>
        <!-- Part neck_plate -->
        <geom type="mesh" class="visual" pos="-0.025 -0.017 -0.0145" quat="0.707107 -0.707107 -2.22045e-16 1.94457e-16" mesh="neck_plate" material="neck_plate_material"/>
        <!-- Part neck_plate_2 -->
        <geom type="mesh" class="visual" pos="0.025 -0.017 -0.0145" quat="1.94457e-16 1.94457e-16 -0.707107 -0.707107" mesh="neck_plate" material="neck_plate_material"/>
        <!-- Part xl330_8 -->
        <geom type="mesh" class="visual" pos="-1.31145e-15 0.043 -0.0145" quat="0.5 -0.5 -0.5 -0.5" mesh="xl330" material="xl330_material"/>
        <!-- Link head_pitch_to_yaw -->
        <body name="head_pitch_to_yaw" pos="-1.31145e-15 0.043 -3.97252e-16" quat="1 -0 4.0766e-17 4.72982e-16">
          <!-- Joint from neck_plate to head_pitch_to_yaw -->
          <joint axis="0 0 1" name="head_pitch" type="hinge" range="-1.2217304763960315 1.2217304763960297" class="chosen_actuator"/>
          <inertial pos="0.00612022 0.0212216 -0.0145" mass="0.00847041" fullinertia="3.01296e-06 1.50757e-06 2.61412e-06 -4.42309e-07 -1.0103e-12 2.76775e-13"/>
          <!-- Part head_pitch_to_yaw -->
          <geom type="mesh" class="visual" pos="0.025 -0.06 -0.0145" quat="3.53503e-16 1.94457e-16 0.707107 0.707107" mesh="head_pitch_to_yaw" material="head_pitch_to_yaw_material"/>
          <!-- Link head_yaw_to_roll -->
          <body name="head_yaw_to_roll" pos="7.84095e-16 0.0465 -0.0145" quat="3.33352e-16 -1.94457e-16 -0.707107 0.707107">
            <!-- Joint from head_pitch_to_yaw to head_yaw_to_roll -->
            <joint axis="0 0 1" name="head_yaw" type="hinge" range="-2.6179938779914944 2.6179938779914944" class="chosen_actuator"/>
            <inertial pos="0.00569587 -1.18296e-17 0.0184874" mass="0.0379676" fullinertia="7.59409e-06 1.62671e-05 1.68278e-05 -4.4508e-22 1.16448e-06 1.35272e-21"/>
            <!-- Part head_yaw_to_roll -->
            <geom type="mesh" class="visual" pos="-0.025 -1.8838e-17 0.1065" quat="9.43277e-46 -1 -6.16298e-32 9.96968e-17" mesh="head_yaw_to_roll" material="head_yaw_to_roll_material"/>
            <!-- Part xl330_9 -->
            <geom type="mesh" class="visual" pos="0 2.43945e-19 0.0145" quat="2.43458e-31 -0.707107 0 0.707107" mesh="xl330" material="xl330_material"/>
            <!-- Link head_base_plate -->
            <body name="head_base_plate" pos="0.0305 -1.8838e-17 0.0145" quat="0.5 -0.5 0.5 -0.5">
              <!-- Joint from head_yaw_to_roll to head_base_plate -->
              <joint axis="0 0 1" name="head_roll" type="hinge" range="-0.5235987755983024 0.5235987755982953" class="chosen_actuator"/>
              <inertial pos="0.00266528 -0.00786002 -0.0193897" mass="0.0728463" fullinertia="0.000144141 0.000159883 3.02801e-05 -1.31809e-06 -7.23983e-06 -4.80384e-06"/>
              <!-- Part xl330_10 -->
              <geom type="mesh" class="visual" pos="-1.72117e-18 0 0.0145" quat="1.69155e-31 -0.707107 1.11022e-16 0.707107" mesh="xl330" material="xl330_material"/>
              <!-- Part bearing_3 -->
              <geom type="mesh" class="visual" pos="-0.02 -2.77556e-16 -0.1215" quat="8.17756e-17 0.707107 0.707107 -8.17756e-17" mesh="bearing" material="bearing_material"/>
              <!-- Part head_base_plate -->
              <geom type="mesh" class="visual" pos="3.41456e-16 -0.092 -0.0556" quat="0.5 -0.5 -0.5 -0.5" mesh="head_base_plate" material="head_base_plate_material"/>
            </body>
          </body>
        </body>
      </body>
      <!-- Link xl330 -->
      <body name="xl330" pos="0.0125644 -0.02 0.0223" quat="0 1 0 0">
        <!-- Joint from trunk_base to xl330 -->
        <joint axis="0 0 1" name="right_hip_yaw" type="hinge" range="-0.3490658503988668 0.349065850398865" class="chosen_actuator"/>
        <inertial pos="0.000237525 6.60812e-18 0.0207938" mass="0.0252944" fullinertia="5.1295e-06 5.67885e-06 2.4759e-06 -3.04571e-23 2.1555e-08 -5.86949e-21"/>
        <!-- Part roll_motor_top_2 -->
        <geom type="mesh" class="visual" pos="-1.73472e-18 0.02 -0.0146" quat="8.03113e-17 1 -0 -3.77504e-34" mesh="roll_motor_top" material="roll_motor_top_material"/>
        <!-- Part roll_motor_bottom_2 -->
        <geom type="mesh" class="visual" pos="5e-05 0.02 -0.0146" quat="8.03113e-17 1 -0 -7.47726e-17" mesh="roll_motor_bottom" material="roll_motor_bottom_material"/>
        <!-- Part xl330_11 -->
        <geom type="mesh" class="visual" pos="5e-05 1.73472e-17 0.0286" quat="1.95716e-31 0 2.22045e-16 1" mesh="xl330" material="xl330_material"/>
        <!-- Link right_roll_to_pitch -->
        <body name="right_roll_to_pitch" pos="0.01455 1.73472e-17 0.0286" quat="0.5 -0.5 0.5 -0.5">
          <!-- Joint from xl330 to right_roll_to_pitch -->
          <joint axis="0 0 1" name="right_hip_roll" type="hinge" range="-0.6981317007977318 0.6981317007977318" class="chosen_actuator"/>
          <inertial pos="-0.0346606 0.000200457 -0.013468" mass="0.0304911" fullinertia="5.39923e-06 9.50247e-06 6.62184e-06 -9.53595e-08 6.01505e-08 2.24922e-08"/>
          <!-- Part right_roll_to_pitch -->
          <geom type="mesh" class="visual" pos="0.02 0.0432 -0.0145" quat="0.5 -0.5 -0.5 -0.5" mesh="right_roll_to_pitch" material="right_roll_to_pitch_material"/>
          <!-- Part xl330_12 -->
          <geom type="mesh" class="visual" pos="-0.0401 7.80626e-18 -0.0245" quat="1.06442e-16 0 -1 -3.74044e-16" mesh="xl330" material="xl330_material"/>
          <!-- Link xl330_2 -->
          <body name="xl330_2" pos="-0.0546 7.80626e-18 -0.0245" quat="0.5 -0.5 -0.5 0.5">
            <!-- Joint from right_roll_to_pitch to xl330_2 -->
            <joint axis="0 0 1" name="right_hip_pitch" type="hinge" range="-1.5707963267948966 -0.0" class="chosen_actuator"/>
            <inertial pos="-0.0289616 -1.52404e-17 -0.0142663" mass="0.0262855" fullinertia="3.72519e-06 7.24907e-06 5.52389e-06 4.78235e-21 2.48125e-08 6.75962e-23"/>
            <!-- Part xl330_13 -->
            <geom type="mesh" class="visual" pos="-0.042 0 -0.0145" quat="9.97848e-17 -0.707107 -0 0.707107" mesh="xl330" material="xl330_material"/>
            <!-- Part leg_plate_5 -->
            <geom type="mesh" class="visual" pos="0.0432 -0.01 0.0455" quat="0.5 -0.5 0.5 -0.5" mesh="leg_plate" material="leg_plate_material"/>
            <!-- Part leg_plate_6 -->
            <geom type="mesh" class="visual" pos="0.0432 0.01 -0.0745" quat="0.5 0.5 0.5 0.5" mesh="leg_plate" material="leg_plate_material"/>
            <!-- Link xl330_3 -->
            <body name="xl330_3" pos="-0.042 1.30104e-17 0" quat="0.707107 8.62279e-17 -5.55112e-17 -0.707107">
              <!-- Joint from xl330_2 to xl330_3 -->
              <joint axis="0 0 1" name="right_knee" type="hinge" range="-8.881784197001252e-16 1.9198621771937616" class="chosen_actuator"/>
              <inertial pos="-3.81199e-17 -0.0289616 -0.0142663" mass="0.0262855" fullinertia="7.24907e-06 3.72519e-06 5.52389e-06 8.28391e-21 -3.02138e-21 2.48125e-08"/>
              <!-- Part xl330_14 -->
              <geom type="mesh" class="visual" pos="-1.64799e-17 -0.042 -0.0145" quat="0.5 0.5 0.5 -0.5" mesh="xl330" material="xl330_material"/>
              <!-- Part leg_plate_7 -->
              <geom type="mesh" class="visual" pos="0.01 0.0432 0.0455" quat="0.707107 -0.707107 -0 9.29117e-17" mesh="leg_plate" material="leg_plate_material"/>
              <!-- Part leg_plate_8 -->
              <geom type="mesh" class="visual" pos="-0.01 0.0432 -0.0745" quat="1.9959e-16 2.77556e-17 -0.707107 -0.707107" mesh="leg_plate" material="leg_plate_material"/>
              <!-- Link foot -->
              <body name="foot" pos="8.76035e-17 -0.042 -1.52656e-16" quat="1 -5.42101e-20 7.36309e-16 -6.11463e-16">
                <!-- Joint from xl330_3 to foot -->
                <joint axis="0 0 1" name="right_ankle" type="hinge" range="-1.5707963267948992 1.570796326794894" class="chosen_actuator"/>
                <inertial pos="0.00475212 -0.0143399 -0.0145" mass="0.0190505" fullinertia="3.25184e-06 6.82459e-06 4.90623e-06 9.55165e-08 2.23326e-11 -8.15886e-12"/>
                <!-- Part foot_2 -->
                <geom type="mesh" class="visual" pos="0.01 0.1272 0.0455" quat="0.707107 -0.707107 -0 -9.13696e-43" mesh="foot" material="foot_material"/>
                <!-- Part foot_tpu_bottom_2 -->
                <geom type="mesh" class="visual" pos="0.01 0.1272 0.0455" quat="0.707107 -0.707107 0 6.1359e-30" mesh="foot_tpu_bottom" material="foot_tpu_bottom_material"/>
                <geom name="right_foot_collision" type="mesh" class="collision" pos="0.01 0.1272 0.0455" quat="0.707107 -0.707107 0 6.1359e-30" mesh="foot_tpu_bottom" material="foot_tpu_bottom_material"/>
                <!-- Frame right_foot -->
                <site group="3" name="right_foot" pos="0.0048 -0.021 -0.0145" quat="0.707107 -0.707107 0 6.1359e-30"/>
              </body>
            </body>
          </body>
        </body>
      </body>
    </body>
  </worldbody>
  <asset>
    <mesh file="head_yaw_to_roll.stl"/>
    <mesh file="right_roll_to_pitch.stl"/>
    <mesh file="cell.stl"/>
    <mesh file="roll_motor_bottom.stl"/>
    <mesh file="uc.stl"/>
    <mesh file="foot_tpu_bottom.stl"/>
    <mesh file="usb_c_charger.stl"/>
    <mesh file="leg_plate.stl"/>
    <mesh file="holder.stl"/>
    <mesh file="ubec_8v_5v_dc_dc.stl"/>
    <mesh file="left_roll_to_pitch.stl"/>
    <mesh file="bms.stl"/>
    <mesh file="head_pitch_to_yaw.stl"/>
    <mesh file="bearing.stl"/>
    <mesh file="bno055.stl"/>
    <mesh file="trunk_yaw.stl"/>
    <mesh file="uc_boards.stl"/>
    <mesh file="power_switch.stl"/>
    <mesh file="neck_plate.stl"/>
    <mesh file="foot.stl"/>
    <mesh file="board.stl"/>
    <mesh file="xl330.stl"/>
    <mesh file="jumper.stl"/>
    <mesh file="head_base_plate.stl"/>
    <mesh file="raspberrypizerow.stl"/>
    <mesh file="trunk_base.stl"/>
    <mesh file="roll_motor_top.stl"/>
    <material name="ubec_8v_5v_dc_dc_material" rgba="0.615686 0.811765 0.929412 1"/>
    <material name="cell_material" rgba="0.615686 0.811765 0.929412 1"/>
    <material name="xl330_material" rgba="0.286275 0.286275 0.286275 1"/>
    <material name="bms_material" rgba="0.231373 0.380392 0.705882 1"/>
    <material name="usb_c_charger_material" rgba="0.615686 0.811765 0.929412 1"/>
    <material name="bearing_material" rgba="0.701961 0.701961 0.701961 1"/>
    <material name="trunk_yaw_material" rgba="0.235294 0.235294 0.235294 1"/>
    <material name="jumper_material" rgba="0.498039 0.498039 0.498039 1"/>
    <material name="holder_material" rgba="0.647059 0.647059 0.647059 1"/>
    <material name="bno055_material" rgba="0.615686 0.811765 0.929412 1"/>
    <material name="raspberrypizerow_material" rgba="0.231373 0.380392 0.705882 1"/>
    <material name="board_material" rgba="0 0.501961 0 1"/>
    <material name="uc_boards_material" rgba="0.972549 0.529412 0.00392157 1"/>
    <material name="trunk_base_material" rgba="0.235294 0.235294 0.235294 1"/>
    <material name="power_switch_material" rgba="0.901961 0.901961 0.901961 1"/>
    <material name="uc_material" rgba="0.768627 0.886275 0.952941 1"/>
    <material name="roll_motor_bottom_material" rgba="0.235294 0.235294 0.235294 1"/>
    <material name="roll_motor_top_material" rgba="0.235294 0.235294 0.235294 1"/>
    <material name="left_roll_to_pitch_material" rgba="0.235294 0.235294 0.235294 1"/>
    <material name="leg_plate_material" rgba="0.235294 0.235294 0.235294 1"/>
    <material name="foot_material" rgba="1 0.756863 0.054902 1"/>
    <material name="foot_tpu_bottom_material" rgba="0.262745 0.262745 0.262745 1"/>
    <material name="neck_plate_material" rgba="0.235294 0.235294 0.235294 1"/>
    <material name="head_pitch_to_yaw_material" rgba="0.235294 0.235294 0.235294 1"/>
    <material name="head_yaw_to_roll_material" rgba="0.235294 0.235294 0.235294 1"/>
    <material name="head_base_plate_material" rgba="0.235294 0.235294 0.235294 1"/>
    <material name="right_roll_to_pitch_material" rgba="0.235294 0.235294 0.235294 1"/>
  </asset>
  <actuator>
    <position class="chosen_actuator" name="left_hip_yaw" joint="left_hip_yaw" inheritrange="1"/>
    <position class="chosen_actuator" name="left_hip_roll" joint="left_hip_roll" inheritrange="1"/>
    <position class="chosen_actuator" name="left_hip_pitch" joint="left_hip_pitch" inheritrange="1"/>
    <position class="chosen_actuator" name="left_knee" joint="left_knee" inheritrange="1"/>
    <position class="chosen_actuator" name="left_ankle" joint="left_ankle" inheritrange="1"/>
    <position class="chosen_actuator" name="neck_pitch" joint="neck_pitch" inheritrange="1"/>
    <position class="chosen_actuator" name="head_pitch" joint="head_pitch" inheritrange="1"/>
    <position class="chosen_actuator" name="head_yaw" joint="head_yaw" inheritrange="1"/>
    <position class="chosen_actuator" name="head_roll" joint="head_roll" inheritrange="1"/>
    <position class="chosen_actuator" name="right_hip_yaw" joint="right_hip_yaw" inheritrange="1"/>
    <position class="chosen_actuator" name="right_hip_roll" joint="right_hip_roll" inheritrange="1"/>
    <position class="chosen_actuator" name="right_hip_pitch" joint="right_hip_pitch" inheritrange="1"/>
    <position class="chosen_actuator" name="right_knee" joint="right_knee" inheritrange="1"/>
    <position class="chosen_actuator" name="right_ankle" joint="right_ankle" inheritrange="1"/>
  </actuator>
  <equality/>
</mujoco>
